<mujoco>
    <option gravity="0 0 -9.81"/>
    <worldbody>
        <light diffuse=".5 .5 .5" pos="0 0 3" dir="0 0 -1"/>
        <geom type="plane" size="5 5 0.1" rgba=".9 .5 .9 1"/>
        <body name="block0" pos="0 0 0">
            <joint type="free"/>
            <geom type="box" size="0.05 0.0568 0.05" rgba="1 0 0 1" euler="0 90 0"/>
    
            <body name="block1" pos="0 0.1246 0">
                <joint name="joint0" pos="0 -0.0678 0" type="hinge" axis="0 0 1" range="-15 0"/>
                <geom type="box" size="0.05 0.0678 0.05" rgba="1 0 0 1" euler="0 90 0"/>
        
                </body>
                
            <body name="block2" pos="0 0.2492 0">
                <joint name="joint1" pos="0 -0.0568 0" type="hinge" axis="0 0 1" range="-15 0"/>
                <geom type="box" size="0.05 0.0568 0.05" rgba="1 0 0 1" euler="0 90 0"/>
        
                </body>
                
            <body name="block3" pos="0 0.3738 0">
                <joint name="joint2" pos="0 -0.0678 0" type="hinge" axis="0 0 1" range="-15 0"/>
                <geom type="box" size="0.05 0.0678 0.05" rgba="1 0 0 1" euler="0 90 0"/>
        
                </body>
                
            <body name="block4" pos="0 0.4984 0">
                <joint name="joint3" pos="0 -0.0568 0" type="hinge" axis="0 0 1" range="-15 0"/>
                <geom type="box" size="0.05 0.0568 0.05" rgba="1 0 0 1" euler="0 90 0"/>
        
                </body>
                
            <body name="block5" pos="0 0.623 0">
                <joint name="joint4" pos="0 -0.0678 0" type="hinge" axis="0 0 1" range="-15 0"/>
                <geom type="box" size="0.05 0.0678 0.05" rgba="1 0 0 1" euler="0 90 0"/>
        
            </body>
        </body>
    </worldbody>
</mujoco>